<?xml version="1.0" ?>
<!-- =================================================================================== -->
<!-- |    This document was autogenerated by xacro from jaime_neck.xacro               | -->
<!-- |    EDITING THIS FILE BY HAND IS NOT RECOMMENDED                                 | -->
<!-- =================================================================================== -->
<robot name="jaime_neck">
  <material name="silver">
    <color rgba="0.700 0.700 0.700 1.000"/>
  </material>
  <transmission name="l1_to_base_link_tran">
    <type>transmission_interface/SimpleTransmission</type>
    <joint name="l1_to_base_link">
      <hardwareInterface>hardware_interface/EffortJointInterface</hardwareInterface>
    </joint>
    <actuator name="l1_to_base_link_actr">
      <hardwareInterface>hardware_interface/EffortJointInterface</hardwareInterface>
      <mechanicalReduction>1</mechanicalReduction>
    </actuator>
  </transmission>
  <transmission name="l2_to_l1_tran">
    <type>transmission_interface/SimpleTransmission</type>
    <joint name="l2_to_l1">
      <hardwareInterface>hardware_interface/EffortJointInterface</hardwareInterface>
    </joint>
    <actuator name="l2_to_l1_actr">
      <hardwareInterface>hardware_interface/EffortJointInterface</hardwareInterface>
      <mechanicalReduction>1</mechanicalReduction>
    </actuator>
  </transmission>
  <transmission name="l3_to_l2_tran">
    <type>transmission_interface/SimpleTransmission</type>
    <joint name="l3_to_l2">
      <hardwareInterface>hardware_interface/EffortJointInterface</hardwareInterface>
    </joint>
    <actuator name="l3_to_l2_actr">
      <hardwareInterface>hardware_interface/EffortJointInterface</hardwareInterface>
      <mechanicalReduction>1</mechanicalReduction>
    </actuator>
  </transmission>
  <transmission name="l4_to_l3_tran">
    <type>transmission_interface/SimpleTransmission</type>
    <joint name="l4_to_l3">
      <hardwareInterface>hardware_interface/EffortJointInterface</hardwareInterface>
    </joint>
    <actuator name="l4_to_l3_actr">
      <hardwareInterface>hardware_interface/EffortJointInterface</hardwareInterface>
      <mechanicalReduction>1</mechanicalReduction>
    </actuator>
  </transmission>
  <transmission name="l5_to_l4_tran">
    <type>transmission_interface/SimpleTransmission</type>
    <joint name="l5_to_l4">
      <hardwareInterface>hardware_interface/EffortJointInterface</hardwareInterface>
    </joint>
    <actuator name="l5_to_l4_actr">
      <hardwareInterface>hardware_interface/EffortJointInterface</hardwareInterface>
      <mechanicalReduction>1</mechanicalReduction>
    </actuator>
  </transmission>
  <transmission name="l6_to_l5_tran">
    <type>transmission_interface/SimpleTransmission</type>
    <joint name="l6_to_l5">
      <hardwareInterface>hardware_interface/EffortJointInterface</hardwareInterface>
    </joint>
    <actuator name="l6_to_l5_actr">
      <hardwareInterface>hardware_interface/EffortJointInterface</hardwareInterface>
      <mechanicalReduction>1</mechanicalReduction>
    </actuator>
  </transmission>
  <gazebo>
    <plugin filename="libgazebo_ros_control.so" name="control"/>
  </gazebo>
  <gazebo reference="base_link">
    <material>Gazebo/Silver</material>
    <mu1>0.2</mu1>
    <mu2>0.2</mu2>
    <selfCollide>true</selfCollide>
    <gravity>true</gravity>
  </gazebo>
  <gazebo reference="l1_1">
    <material>Gazebo/Silver</material>
    <mu1>0.2</mu1>
    <mu2>0.2</mu2>
    <selfCollide>true</selfCollide>
  </gazebo>
  <gazebo reference="l2_1">
    <material>Gazebo/Silver</material>
    <mu1>0.2</mu1>
    <mu2>0.2</mu2>
    <selfCollide>true</selfCollide>
  </gazebo>
  <gazebo reference="l3_1">
    <material>Gazebo/Silver</material>
    <mu1>0.2</mu1>
    <mu2>0.2</mu2>
    <selfCollide>true</selfCollide>
  </gazebo>
  <gazebo reference="l4_1">
    <material>Gazebo/Silver</material>
    <mu1>0.2</mu1>
    <mu2>0.2</mu2>
    <selfCollide>true</selfCollide>
  </gazebo>
  <gazebo reference="l5_1">
    <material>Gazebo/Silver</material>
    <mu1>0.2</mu1>
    <mu2>0.2</mu2>
    <selfCollide>true</selfCollide>
  </gazebo>
  <gazebo reference="l6_1">
    <material>Gazebo/Silver</material>
    <mu1>0.2</mu1>
    <mu2>0.2</mu2>
    <selfCollide>true</selfCollide>
  </gazebo>
  <link name="base_link">
    <inertial>
      <origin rpy="0 0 0" xyz="-0.0015071371607443052 -0.045178581236278964 0.1966099517276674"/>
      <mass value="49.1345111063547"/>
      <inertia ixx="1.874356" ixy="0.0" ixz="0.472297" iyy="2.194951" iyz="-0.0" izz="0.476531"/>
    </inertial>
    <visual>
      <origin rpy="0 0 0" xyz="0 0 0"/>
      <geometry>
        <mesh filename="package://jaime_neck_description/meshes/base_link.stl" scale="0.001 0.001 0.001"/>
      </geometry>
      <material name="silver"/>
    </visual>
    <collision>
      <origin rpy="0 0 0" xyz="0 0 0"/>
      <geometry>
        <mesh filename="package://jaime_neck_description/meshes/base_link.stl" scale="0.001 0.001 0.001"/>
      </geometry>
    </collision>
  </link>
  <link name="l1_1">
    <inertial>
      <origin rpy="0 0 0" xyz="-0.02269974234167807 -0.014999581236279005 0.0445499817871311"/>
      <mass value="1.237938027968155"/>
      <inertia ixx="0.001558" ixy="0.0" ixz="0.000668" iyy="0.001961" iyz="-0.0" izz="0.000588"/>
    </inertial>
    <visual>
      <origin rpy="0 0 0" xyz="0.194767 0.030179 -0.781292"/>
      <geometry>
        <mesh filename="package://jaime_neck_description/meshes/l1_1.stl" scale="0.001 0.001 0.001"/>
      </geometry>
      <material name="silver"/>
    </visual>
    <collision>
      <origin rpy="0 0 0" xyz="0.194767 0.030179 -0.781292"/>
      <geometry>
        <mesh filename="package://jaime_neck_description/meshes/l1_1.stl" scale="0.001 0.001 0.001"/>
      </geometry>
    </collision>
  </link>
  <link name="l2_1">
    <inertial>
      <origin rpy="0 0 0" xyz="-0.04766928370441903 -0.014999581236279012 0.09355598476474769"/>
      <mass value="1.5249840239746273"/>
      <inertia ixx="0.003613" ixy="0.0" ixz="0.001596" iyy="0.004325" iyz="-0.0" izz="0.001294"/>
    </inertial>
    <visual>
      <origin rpy="0 0 0" xyz="0.240166 0.030179 -0.870392"/>
      <geometry>
        <mesh filename="package://jaime_neck_description/meshes/l2_1.stl" scale="0.001 0.001 0.001"/>
      </geometry>
      <material name="silver"/>
    </visual>
    <collision>
      <origin rpy="0 0 0" xyz="0.240166 0.030179 -0.870392"/>
      <geometry>
        <mesh filename="package://jaime_neck_description/meshes/l2_1.stl" scale="0.001 0.001 0.001"/>
      </geometry>
    </collision>
  </link>
  <link name="l3_1">
    <inertial>
      <origin rpy="0 0 0" xyz="-0.024969768568086748 -0.014999581236279102 0.04900502573654353"/>
      <mass value="1.3321380279681612"/>
      <inertia ixx="0.001918" ixy="0.0" ixz="0.000841" iyy="0.002414" iyz="-0.0" izz="0.000696"/>
    </inertial>
    <visual>
      <origin rpy="0 0 0" xyz="0.335504 0.030179 -1.057504"/>
      <geometry>
        <mesh filename="package://jaime_neck_description/meshes/l3_1.stl" scale="0.001 0.001 0.001"/>
      </geometry>
      <material name="silver"/>
    </visual>
    <collision>
      <origin rpy="0 0 0" xyz="0.335504 0.030179 -1.057504"/>
      <geometry>
        <mesh filename="package://jaime_neck_description/meshes/l3_1.stl" scale="0.001 0.001 0.001"/>
      </geometry>
    </collision>
  </link>
  <link name="l4_1">
    <inertial>
      <origin rpy="0 0 0" xyz="-0.0419943547369534 -0.014999581236279088 0.08241849444516047"/>
      <mass value="1.2109840372908334"/>
      <inertia ixx="0.002516" ixy="0.0" ixz="0.001079" iyy="0.002965" iyz="-0.0" izz="0.000948"/>
    </inertial>
    <visual>
      <origin rpy="0 0 0" xyz="0.385443 0.030179 -1.155514"/>
      <geometry>
        <mesh filename="package://jaime_neck_description/meshes/l4_1.stl" scale="0.001 0.001 0.001"/>
      </geometry>
      <material name="silver"/>
    </visual>
    <collision>
      <origin rpy="0 0 0" xyz="0.385443 0.030179 -1.155514"/>
      <geometry>
        <mesh filename="package://jaime_neck_description/meshes/l4_1.stl" scale="0.001 0.001 0.001"/>
      </geometry>
    </collision>
  </link>
  <link name="l5_1">
    <inertial>
      <origin rpy="0 0 0" xyz="-0.016114391661114558 -0.01499958123627861 0.03162496588110897"/>
      <mass value="0.9654457744721715"/>
      <inertia ixx="0.000778" ixy="0.0" ixz="0.000298" iyy="0.000983" iyz="-0.0" izz="0.000346"/>
    </inertial>
    <visual>
      <origin rpy="0 0 0" xyz="0.469431 0.030179 -1.320351"/>
      <geometry>
        <mesh filename="package://jaime_neck_description/meshes/l5_1.stl" scale="0.001 0.001 0.001"/>
      </geometry>
      <material name="silver"/>
    </visual>
    <collision>
      <origin rpy="0 0 0" xyz="0.469431 0.030179 -1.320351"/>
      <geometry>
        <mesh filename="package://jaime_neck_description/meshes/l5_1.stl" scale="0.001 0.001 0.001"/>
      </geometry>
    </collision>
  </link>
  <link name="l6_1">
    <inertial>
      <origin rpy="0 0 0" xyz="-0.012920274632011619 4.1876372177535037e-07 0.06941179014315724"/>
      <mass value="3.703390903699381"/>
      <inertia ixx="0.013166" ixy="0.0" ixz="-0.006791" iyy="0.01768" iyz="-0.0" izz="0.023034"/>
    </inertial>
    <visual>
      <origin rpy="0 0 0" xyz="0.521301 0.045179 -1.378096"/>
      <geometry>
        <mesh filename="package://jaime_neck_description/meshes/l6_1.stl" scale="0.001 0.001 0.001"/>
      </geometry>
      <material name="silver"/>
    </visual>
    <collision>
      <origin rpy="0 0 0" xyz="0.521301 0.045179 -1.378096"/>
      <geometry>
        <mesh filename="package://jaime_neck_description/meshes/l6_1.stl" scale="0.001 0.001 0.001"/>
      </geometry>
    </collision>
  </link>
  <joint name="l1_to_base_link" type="revolute">
    <origin rpy="0 0 0" xyz="-0.194767 -0.030179 0.781292"/>
    <parent link="base_link"/>
    <child link="l1_1"/>
    <axis xyz="0.0 1.0 -0.0"/>
    <limit effort="100" lower="0.0" upper="0.872665" velocity="100"/>
  </joint>
  <joint name="l2_to_l1" type="revolute">
    <origin rpy="0 0 0" xyz="-0.045399 0.0 0.0891"/>
    <parent link="l1_1"/>
    <child link="l2_1"/>
    <axis xyz="0.0 1.0 -0.0"/>
    <limit effort="100" lower="0.0" upper="0.872665" velocity="100"/>
    <mimic joint="l1_to_base_link" multiplier="1.0" offset="0.0"/>
  </joint>
  <joint name="l3_to_l2" type="revolute">
    <origin rpy="0 0 0" xyz="-0.095338 0.0 0.187112"/>
    <parent link="l2_1"/>
    <child link="l3_1"/>
    <axis xyz="-0.0 1.0 -0.0"/>
    <limit effort="100" lower="0.0" upper="0.872665" velocity="100"/>
  </joint>
  <joint name="l4_to_l3" type="revolute">
    <origin rpy="0 0 0" xyz="-0.049939 0.0 0.09801"/>
    <parent link="l3_1"/>
    <child link="l4_1"/>
    <axis xyz="0.0 1.0 -0.0"/>
    <limit effort="100" lower="0.0" upper="0.872665" velocity="100"/>
    <mimic joint="l3_to_l2" multiplier="1.0" offset="0.0"/>
  </joint>
  <joint name="l5_to_l4" type="revolute">
    <origin rpy="0 0 0" xyz="-0.083988 0.0 0.164837"/>
    <parent link="l4_1"/>
    <child link="l5_1"/>
    <axis xyz="-0.0 1.0 -0.0"/>
    <limit effort="100" lower="-1.570796" upper="1.570796" velocity="100"/>
  </joint>
  <joint name="l6_to_l5" type="revolute">
    <origin rpy="0 0 0" xyz="-0.05187 -0.015 0.057745"/>
    <parent link="l5_1"/>
    <child link="l6_1"/>
    <axis xyz="-0.891007 -0.0 -0.45399"/>
    <limit effort="100" lower="-1.570796" upper="1.570796" velocity="100"/>
  </joint>
</robot>
